Workbook

Sheet 01_手动输入
A1: CATL 四层映射引擎 Demo - 手动输入总表
A2: 说明：只有本 Sheet 允许手动修改。黄色列是实际输入值，后面所有 Sheet 都由公式自动拉取与计算。
A3: 类别 | B3: 字段代码 | C3: 手动输入项（中文） | D3: 英文对应 | E3: 单位 | F3: 示例值 | G3: 实际输入值 | H3: 说明 | I3: 常见证据 | J3: 主要影响输出
A4: A. 基本身份 | B4: manufacturer_name | C4: 制造商名称 | D4: manufacturer name | E4: 文本 | F4: CATL | G4: CATL | H4: 公司主体识别字段 | I4: 营业执照/年报 | J4: EU+CBAM
A5: A. 基本身份 | B5: product_name | C5: 演示产品名称 | D5: demo product name | E5: 文本 | F5: 神行 PLUS CTP 动力电池包（Demo） | G5: 神行 PLUS CTP 动力电池包（Demo） | H5: 比赛讲述用产品名 | I5: 产品主数据 | J5: EU
A6: A. 基本身份 | B6: model_code | C6: 电池型号代码 | D6: battery model identifier | E6: 文本 | F6: SXP-CTP-PACK-DEMO-01 | G6: SXP-CTP-PACK-DEMO-01 | H6: 四层映射的产品锚点 | I6: 型号注册表 | J6: EU+CBAM
A7: A. 基本身份 | B7: battery_category | C7: 产品类别 | D7: battery category | E7: 文本 | F7: EV battery | G7: EV battery | H7: 动力电池场景 | I7: 技术规格书 | J7: EU
A8: A. 基本身份 | B8: chemistry | C8: 化学体系 | D8: chemistry | E8: 文本 | F8: LFP（磷酸铁锂） | G8: LFP（磷酸铁锂） | H8: 影响材料追踪范围 | I8: BOM/规格书 | J8: EU+CBAM
A9: A. 基本身份 | B9: plant_code | C9: 制造工厂代码 | D9: plant code | E9: 文本 | F9: CN-JS-PLANT-DEMO-01 | G9: CN-JS-PLANT-DEMO-01 | H9: EU 强调 plant 级 | I9: 工厂注册表 | J9: EU+CBAM
A10: A. 基本身份 | B10: plant_name | C10: 制造工厂名称 | D10: plant name | E10: 文本 | F10: 江苏时代（Demo） | G10: 江苏时代（Demo） | H10: 便于人读 | I10: 工厂主数据 | J10: EU
A11: A. 基本身份 | B11: reporting_period | C11: 产品报告期 | D11: reporting period | E11: 文本 | F11: 2025Q4 | G11: 2025Q4 | H11: 要从年报周期转成产品周期 | I11: 排产记录 | J11: EU+CBAM
A12: A. 基本身份 | B12: pack_capacity_kwh | C12: 电池包额定容量 | D12: pack capacity | E12: kWh | F12: 72 | G12: 72 | H12: 用于转换 kgCO2e/kWh | I12: 规格书/测试报告 | J12: EU
A13: A. 基本身份 | B13: nominal_voltage_v | C13: 标称电压 | D13: nominal voltage | E13: V | F13: 800 | G13: 800 | H13: 产品公开参数 | I13: 规格书/测试报告 | J13: EU
A14: A. 基本身份 | B14: cycle_life_cycles | C14: 循环寿命 | D14: cycle life | E14: cycles | F14: 4000 | G14: 4000 | H14: 护照参数层 | I14: 测试报告 | J14: EU
A15: A. 基本身份 | B15: individual_battery_prefix | C15: 个体电池编码前缀 | D15: battery prefix | E15: 文本 | F15: SXP25Q4 | G15: SXP25Q4 | H15: 用于序列化 | I15: 序列化规则 | J15: EU
A16: A. 基本身份 | B16: due_diligence_policy_url | C16: 尽调政策链接 | D16: due diligence policy URL | E16: 文本 | F16: https://www.catl.com/ | G16: https://www.catl.com/ | H16: 尽调公开字段 | I16: 政策文件/官网 | J16: EU
A17: A. 基本身份 | B17: qr_object_id | C17: 护照对象 ID | D17: passport object id | E17: 文本 | F17: passport-demo-001 | G17: passport-demo-001 | H17: 数字护照对象键 | I17: 护照系统对象 ID | J17: EU
A18: B. 合规准备状态 | B18: pcf_study_status | C18: 产品碳足迹研究底稿状态 | D18: PCF study status | E18: 文本 | F18: 齐备 | G18: 齐备 | H18: 碳足迹声明底稿是否齐备 | I18: PCF 研究底稿 | J18: EU
A19: B. 合规准备状态 | B19: test_report_status | C19: 测试报告状态 | D19: test report status | E19: 文本 | F19: 齐备 | G19: 齐备 | H19: 正式合规评估硬材料 | I19: 测试报告原件 | J19: EU
A20: B. 合规准备状态 | B20: technical_doc_status | C20: 技术文档状态 | D20: technical documentation status | E20: 文本 | F20: 齐备 | G20: 齐备 | H20: Annex VIII 关键材料 | I20: 图纸/说明书/计算书 | J20: EU
A21: B. 合规准备状态 | B21: third_party_verification_status | C21: 第三方核验状态 | D21: third-party verification status | E21: 文本 | F21: 已核验 | G21: 已核验 | H21: 碳足迹/再生料/上游 PCF 关键状态 | I21: 核验声明 | J21: EU+CBAM
A22: B. 合规准备状态 | B22: passport_data_package_status | C22: 护照数据包状态 | D22: passport data package status | E22: 文本 | F22: 齐备 | G22: 齐备 | H22: 决定护照对象能否生成 | I22: 结构化数据包 | J22: EU
A23: B. 合规准备状态 | B23: access_matrix_status | C23: 分层访问矩阵状态 | D23: access matrix status | E23: 文本 | F23: 齐备 | G23: 齐备 | H23: 保护数据主权的关键控制项 | I23: 访问矩阵文档 | J23: EU+CBAM
A24: B. 合规准备状态 | B24: supplier_traceability_coverage_pct | C24: 供应链追溯覆盖率 | D24: traceability coverage | E24: % | F24: 0.92 | G24: 0.92 | H24: 越高越能支撑尽调与追溯 | I24: 追溯台账 | J24: EU+CBAM
A25: B. 合规准备状态 | B25: supplier_pcf_coverage_pct | C25: 供应商 PCF 覆盖率 | D25: supplier PCF coverage | E25: % | F25: 0.76 | G25: 0.76 | H25: 决定上游碳数据基础强度 | I25: 供应商 PCF 报告 | J25: EU+CBAM
A26: B. 合规准备状态 | B26: critical_material_scope | C26: 关键原材料追溯范围 | D26: critical material scope | E26: 文本 | F26: lithium / graphite / aluminium / copper / steel | G26: lithium / graphite / aluminium / copper / steel | H26: 当前 demo 覆盖的关键原材料 | I26: BOM/追溯记录 | J26: EU+CBAM
A27: C. 材料用量 | B27: cathode_mass_kg | C27: 正极材料质量 | D27: cathode mass | E27: kg/pack | F27: 140 | G27: 140 | H27: 原材料阶段输入 | I27: BOM | J27: EU
A28: C. 材料用量 | B28: anode_mass_kg | C28: 负极材料质量 | D28: anode mass | E28: kg/pack | F28: 70 | G28: 70 | H28: 原材料阶段输入 | I28: BOM | J28: EU
A29: C. 材料用量 | B29: electrolyte_mass_kg | C29: 电解液质量 | D29: electrolyte mass | E29: kg/pack | F29: 35 | G29: 35 | H29: 原材料阶段输入 | I29: BOM | J29: EU
A30: C. 材料用量 | B30: separator_mass_kg | C30: 隔膜质量 | D30: separator mass | E30: kg/pack | F30: 12 | G30: 12 | H30: 原材料阶段输入 | I30: BOM | J30: EU
A31: C. 材料用量 | B31: copper_mass_kg | C31: 铜材质量 | D31: copper mass | E31: kg/pack | F31: 50 | G31: 50 | H31: 原材料阶段输入 | I31: BOM | J31: EU
A32: C. 材料用量 | B32: aluminium_mass_kg | C32: 铝材质量 | D32: aluminium mass | E32: kg/pack | F32: 80 | G32: 80 | H32: EU 与 CBAM 共同关注 | I32: BOM | J32: EU+CBAM
A33: C. 材料用量 | B33: steel_mass_kg | C33: 钢材质量 | D33: steel mass | E33: kg/pack | F33: 30 | G33: 30 | H33: EU 与 CBAM 共同关注 | I33: BOM | J33: EU+CBAM
A34: C. 材料用量 | B34: plastic_mass_kg | C34: 塑料件质量 | D34: plastic mass | E34: kg/pack | F34: 25 | G34: 25 | H34: 原材料阶段输入 | I34: BOM | J34: EU
A35: C. 材料用量 | B35: other_material_mass_kg | C35: 其他材料质量 | D35: other material mass | E35: kg/pack | F35: 100 | G35: 100 | H35: 给 demo 留出杂项空间 | I35: BOM | J35: EU
A36: D. 材料排放因子 | B36: cathode_pcf | C36: 正极材料排放因子 | D36: cathode PCF | E36: kgCO2e/kg | F36: 5 | G36: 5 | H36: 供应商 PCF 或行业因子 | I36: 供应商 PCF / 因子库 | J36: EU
A37: D. 材料排放因子 | B37: anode_pcf | C37: 负极材料排放因子 | D37: anode PCF | E37: kgCO2e/kg | F37: 6.5 | G37: 6.5 | H37: 供应商 PCF 或行业因子 | I37: 供应商 PCF / 因子库 | J37: EU
A38: D. 材料排放因子 | B38: electrolyte_pcf | C38: 电解液排放因子 | D38: electrolyte PCF | E38: kgCO2e/kg | F38: 8 | G38: 8 | H38: 供应商 PCF 或行业因子 | I38: 供应商 PCF / 因子库 | J38: EU
... A65: G. 再生材料 | B65: recycled_steel_pct | C65: 再生钢占比 | D65: recycled steel share | E65: % | F65: 0.22 | G65: 0.22 | H65: 有助于上游减碳叙事 | I65: 质量平衡/供应商声明 | J65: EU+CBAM
A66: H. CBAM 影子输入 | B66: aluminium_supplier_installation_id | C66: 铝材供应商安装点 ID | D66: aluminium installation ID | E66: 文本 | F66: AL-SUP-001 | G66: AL-SUP-001 | H66: 借鉴 CBAM installation 逻辑 | I66: 供应商安装点主数据 | J66: CBAM
...

Sheet 02_欧盟电池法输出
A1: 02_欧盟电池法输出（全部自动公式）
A2: 说明：本 Sheet 不允许手动输入，只展示系统自动生成的结果。
A3: 模块 | B3: 输出字段 | C3: 单位 | D3: 自动输出值 | E3: 证据状态 | F3: 核验层级 | G3: 访问层级 | H3: 当前状态
A4: 基本信息 | B4: 制造商名称 | C4: 文本 | D4: =IFERROR(INDEX('09_EU中间表'!$D:$D,MATCH(B4,'09_EU中间表'!$B:$B,0)),"") | E4: =IFERROR(INDEX('05_证据映射过程'!$E:$E,MATCH(B4,'05_证据映射过程'!$B:$B,0)),"不适用/默认") | F4: =IFERROR(INDEX('06_核验映射过程'!$D:$D,MATCH(B4,'06_核验映射过程'!$B:$B,0)),"默认") | G4: =IFERROR(INDEX('07_权限映射过程'!$D:$D,MATCH(B4,'07_权限映射过程'!$B:$B,0)),"默认") | H4: =IF(D4="","待生成","已生成")
A5: 基本信息 | B5: 演示产品名称 | C5: 文本 | D5: =IFERROR(INDEX('09_EU中间表'!$D:$D,MATCH(B5,'09_EU中间表'!$B:$B,0)),"") | E5: =IFERROR(INDEX('05_证据映射过程'!$E:$E,MATCH(B5,'05_证据映射过程'!$B:$B,0)),"不适用/默认") | F5: =IFERROR(INDEX('06_核验映射过程'!$D:$D,MATCH(B5,'06_核验映射过程'!$B:$B,0)),"默认") | G5: =IFERROR(INDEX('07_权限映射过程'!$D:$D,MATCH(B5,'07_权限映射过程'!$B:$B,0)),"默认") | H5: =IF(D5="","待生成","已生成")
A6: 基本信息 | B6: 电池型号 | C6: 文本 | D6: =IFERROR(INDEX('09_EU中间表'!$D:$D,MATCH(B6,'09_EU中间表'!$B:$B,0)),"") | E6: =IFERROR(INDEX('05_证据映射过程'!$E:$E,MATCH(B6,'05_证据映射过程'!$B:$B,0)),"不适用/默认") | F6: =IFERROR(INDEX('06_核验映射过程'!$D:$D,MATCH(B6,'06_核验映射过程'!$B:$B,0)),"默认") | G6: =IFERROR(INDEX('07_权限映射过程'!$D:$D,MATCH(B6,'07_权限映射过程'!$B:$B,0)),"默认") | H6: =IF(D6="","待生成","已生成")
A7: 基本信息 | B7: 产品类别 | C7: 文本 | D7: =IFERROR(INDEX('09_EU中间表'!$D:$D,MATCH(B7,'09_EU中间表'!$B:$B,0)),"") | E7: =IFERROR(INDEX('05_证据映射过程'!$E:$E,MATCH(B7,'05_证据映射过程'!$B:$B,0)),"不适用/默认") | F7: =IFERROR(INDEX('06_核验映射过程'!$D:$D,MATCH(B7,'06_核验映射过程'!$B:$B,0)),"默认") | G7: =IFERROR(INDEX('07_权限映射过程'!$D:$D,MATCH(B7,'07_权限映射过程'!$B:$B,0)),"默认") | H7: =IF(D7="","待生成","已生成")
A8: 基本信息 | B8: 化学体系 | C8: 文本 | D8: =IFERROR(INDEX('09_EU中间表'!$D:$D,MATCH(B8,'09_EU中间表'!$B:$B,0)),"") | E8: =IFERROR(INDEX('05_证据映射过程'!$E:$E,MATCH(B8,'05_证据映射过程'!$B:$B,0)),"不适用/默认") | F8: =IFERROR(INDEX('06_核验映射过程'!$D:$D,MATCH(B8,'06_核验映射过程'!$B:$B,0)),"默认") | G8: =IFERROR(INDEX('07_权限映射过程'!$D:$D,MATCH(B8,'07_权限映射过程'!$B:$B,0)),"默认") | H8: =IF(D8="","待生成","已生成")
A9: 基本信息 | B9: 制造工厂代码 | C9: 文本 | D9: =IFERROR(INDEX('09_EU中间表'!$D:$D,MATCH(B9,'09_EU中间表'!$B:$B,0)),"") | E9: =IFERROR(INDEX('05_证据映射过程'!$E:$E,MATCH(B9,'05_证据映射过程'!$B:$B,0)),"不适用/默认") | F9: =IFERROR(INDEX('06_核验映射过程'!$D:$D,MATCH(B9,'06_核验映射过程'!$B:$B,0)),"默认") | G9: =IFERROR(INDEX('07_权限映射过程'!$D:$D,MATCH(B9,'07_权限映射过程'!$B:$B,0)),"默认") | H9: =IF(D9="","待生成","已生成")
A10: 基本信息 | B10: 制造工厂名称 | C10: 文本 | D10: =IFERROR(INDEX('09_EU中间表'!$D:$D,MATCH(B10,'09_EU中间表'!$B:$B,0)),"") | E10: =IFERROR(INDEX('05_证据映射过程'!$E:$E,MATCH(B10,'05_证据映射过程'!$B:$B,0)),"不适用/默认") | F10: =IFERROR(INDEX('06_核验映射过程'!$D:$D,MATCH(B10,'06_核验映射过程'!$B:$B,0)),"默认") | G10: =IFERROR(INDEX('07_权限映射过程'!$D:$D,MATCH(B10,'07_权限映射过程'!$B:$B,0)),"默认") | H10: =IF(D10="","待生成","已生成")
A11: 基本信息 | B11: 报告期 | C11: 文本 | D11: =IFERROR(INDEX('09_EU中间表'!$D:$D,MATCH(B11,'09_EU中间表'!$B:$B,0)),"") | E11: =IFERROR(INDEX('05_证据映射过程'!$E:$E,MATCH(B11,'05_证据映射过程'!$B:$B,0)),"不适用/默认") | F11: =IFERROR(INDEX('06_核验映射过程'!$D:$D,MATCH(B11,'06_核验映射过程'!$B:$B,0)),"默认") | G11: =IFERROR(INDEX('07_权限映射过程'!$D:$D,MATCH(B11,'07_权限映射过程'!$B:$B,0)),"默认") | H11: =IF(D11="","待生成","已生成")
A12: 产品参数 | B12: 额定容量(kWh) | C12: kWh | D12: =IFERROR(INDEX('09_EU中间表'!$D:$D,MATCH(B12,'09_EU中间表'!$B:$B,0)),"") | E12: =IFERROR(INDEX('05_证据映射过程'!$E:$E,MATCH(B12,'05_证据映射过程'!$B:$B,0)),"不适用/默认") | F12: =IFERROR(INDEX('06_核验映射过程'!$D:$D,MATCH(B12,'06_核验映射过程'!$B:$B,0)),"默认") | G12: =IFERROR(INDEX('07_权限映射过程'!$D:$D,MATCH(B12,'07_权限映射过程'!$B:$B,0)),"默认") | H12: =IF(D12="","待生成","已生成")
A13: 产品参数 | B13: 标称电压(V) | C13: V | D13: =IFERROR(INDEX('09_EU中间表'!$D:$D,MATCH(B13,'09_EU中间表'!$B:$B,0)),"") | E13: =IFERROR(INDEX('05_证据映射过程'!$E:$E,MATCH(B13,'05_证据映射过程'!$B:$B,0)),"不适用/默认") | F13: =IFERROR(INDEX('06_核验映射过程'!$D:$D,MATCH(B13,'06_核验映射过程'!$B:$B,0)),"默认") | G13: =IFERROR(INDEX('07_权限映射过程'!$D:$D,MATCH(B13,'07_权限映射过程'!$B:$B,0)),"默认") | H13: =IF(D13="","待生成","已生成")
A14: 产品参数 | B14: 循环寿命(cycles) | C14: cycles | D14: =IFERROR(INDEX('09_EU中间表'!$D:$D,MATCH(B14,'09_EU中间表'!$B:$B,0)),"") | E14: =IFERROR(INDEX('05_证据映射过程'!$E:$E,MATCH(B14,'05_证据映射过程'!$B:$B,0)),"不适用/默认") | F14: =IFERROR(INDEX('06_核验映射过程'!$D:$D,MATCH(B14,'06_核验映射过程'!$B:$B,0)),"默认") | G14: =IFERROR(INDEX('07_权限映射过程'!$D:$D,MATCH(B14,'07_权限映射过程'!$B:$B,0)),"默认") | H14: =IF(D14="","待生成","已生成")
A15: 碳足迹 | B15: 声明总碳足迹(kgCO2e/pack) | C15: kgCO2e/pack | D15: =IFERROR(INDEX('09_EU中间表'!$D:$D,MATCH(B15,'09_EU中间表'!$B:$B,0)),"") | E15: =IFERROR(INDEX('05_证据映射过程'!$E:$E,MATCH(B15,'05_证据映射过程'!$B:$B,0)),"不适用/默认") | F15: =IFERROR(INDEX('06_核验映射过程'!$D:$D,MATCH(B15,'06_核验映射过程'!$B:$B,0)),"默认") | G15: =IFERROR(INDEX('07_权限映射过程'!$D:$D,MATCH(B15,'07_权限映射过程'!$B:$B,0)),"默认") | H15: =IF(D15="","待生成","已生成")
... A34: 综合状态 | B34: EU 输出结论 | C34: 文本 | D34: =IFERROR(INDEX('09_EU中间表'!$D:$D,MATCH(B34,'09_EU中间表'!$B:$B,0)),"") | E34: =IFERROR(INDEX('05_证据映射过程'!$E:$E,MATCH(B34,'05_证据映射过程'!$B:$B,0)),"不适用/默认") | F34: =IFERROR(INDEX('06_核验映射过程'!$D:$D,MATCH(B34,'06_核验映射过程'!$B:$B,0)),"默认") | G34: =IFERROR(INDEX('07_权限映射过程'!$D:$D,MATCH(B34,'07_权限映射过程'!$B:$B,0)),"默认") | H34: =IF(D34="","待生成","已生成")

Sheet 03_CBAM输出
A1: 03_CBAM输出（全部自动公式）
A2: 说明：本 Sheet 不允许手动输入，只展示系统自动生成的结果。
A3: 模块 | B3: 输出字段 | C3: 单位 | D3: 自动输出值 | E3: 证据状态 | F3: 核验层级 | G3: 访问层级 | H3: 当前状态
A4: 基础锚点 | B4: 电池型号 | C4: 文本 | D4: =IFERROR(INDEX('10_CBAM中间表'!$D:$D,MATCH(B4,'10_CBAM中间表'!$B:$B,0)),"") | E4: =IFERROR(INDEX('05_证据映射过程'!$E:$E,MATCH(B4,'05_证据映射过程'!$B:$B,0)),"不适用/默认") | F4: =IFERROR(INDEX('06_核验映射过程'!$D:$D,MATCH(B4,'06_核验映射过程'!$B:$B,0)),"默认") | G4: =IFERROR(INDEX('07_权限映射过程'!$D:$D,MATCH(B4,'07_权限映射过程'!$B:$B,0)),"默认") | H4: =IF(D4="","待生成","已生成")
A5: 基础锚点 | B5: 产品报告期 | C5: 文本 | D5: =IFERROR(INDEX('10_CBAM中间表'!$D:$D,MATCH(B5,'10_CBAM中间表'!$B:$B,0)),"") | E5: =IFERROR(INDEX('05_证据映射过程'!$E:$E,MATCH(B5,'05_证据映射过程'!$B:$B,0)),"不适用/默认") | F5: =IFERROR(INDEX('06_核验映射过程'!$D:$D,MATCH(B5,'06_核验映射过程'!$B:$B,0)),"默认") | G5: =IFERROR(INDEX('07_权限映射过程'!$D:$D,MATCH(B5,'07_权限映射过程'!$B:$B,0)),"默认") | H5: =IF(D5="","待生成","已生成")
A6: 基础锚点 | B6: 上游材料报告期 | C6: 文本 | D6: =IFERROR(INDEX('10_CBAM中间表'!$D:$D,MATCH(B6,'10_CBAM中间表'!$B:$B,0)),"") | E6: =IFERROR(INDEX('05_证据映射过程'!$E:$E,MATCH(B6,'05_证据映射过程'!$B:$B,0)),"不适用/默认") | F6: =IFERROR(INDEX('06_核验映射过程'!$D:$D,MATCH(B6,'06_核验映射过程'!$B:$B,0)),"默认") | G6: =IFERROR(INDEX('07_权限映射过程'!$D:$D,MATCH(B6,'07_权限映射过程'!$B:$B,0)),"默认") | H6: =IF(D6="","待生成","已生成")
A7: 铝材模块 | B7: 铝材供应商安装点 ID | C7: 文本 | D7: =IFERROR(INDEX('10_CBAM中间表'!$D:$D,MATCH(B7,'10_CBAM中间表'!$B:$B,0)),"") | E7: =IFERROR(INDEX('05_证据映射过程'!$E:$E,MATCH(B7,'05_证据映射过程'!$B:$B,0)),"不适用/默认") | F7: =IFERROR(INDEX('06_核验映射过程'!$D:$D,MATCH(B7,'06_核验映射过程'!$B:$B,0)),"默认") | G7: =IFERROR(INDEX('07_权限映射过程'!$D:$D,MATCH(B7,'07_权限映射过程'!$B:$B,0)),"默认") | H7: =IF(D7="","待生成","已生成")
A8: 铝材模块 | B8: 铝材质量(kg) | C8: kg | D8: =IFERROR(INDEX('10_CBAM中间表'!$D:$D,MATCH(B8,'10_CBAM中间表'!$B:$B,0)),"") | E8: =IFERROR(INDEX('05_证据映射过程'!$E:$E,MATCH(B8,'05_证据映射过程'!$B:$B,0)),"不适用/默认") | F8: =IFERROR(INDEX('06_核验映射过程'!$D:$D,MATCH(B8,'06_核验映射过程'!$B:$B,0)),"默认") | G8: =IFERROR(INDEX('07_权限映射过程'!$D:$D,MATCH(B8,'07_权限映射过程'!$B:$B,0)),"默认") | H8: =IF(D8="","待生成","已生成")
A9: 铝材模块 | B9: 铝材直接排放因子(kgCO2e/kg) | C9: kgCO2e/kg | D9: =IFERROR(INDEX('10_CBAM中间表'!$D:$D,MATCH(B9,'10_CBAM中间表'!$B:$B,0)),"") | E9: =IFERROR(INDEX('05_证据映射过程'!$E:$E,MATCH(B9,'05_证据映射过程'!$B:$B,0)),"不适用/默认") | F9: =IFERROR(INDEX('06_核验映射过程'!$D:$D,MATCH(B9,'06_核验映射过程'!$B:$B,0)),"默认") | G9: =IFERROR(INDEX('07_权限映射过程'!$D:$D,MATCH(B9,'07_权限映射过程'!$B:$B,0)),"默认") | H9: =IF(D9="","待生成","已生成")
A10: 铝材模块 | B10: 铝材间接排放因子(kgCO2e/kg) | C10: kgCO2e/kg | D10: =IFERROR(INDEX('10_CBAM中间表'!$D:$D,MATCH(B10,'10_CBAM中间表'!$B:$B,0)),"") | E10: =IFERROR(INDEX('05_证据映射过程'!$E:$E,MATCH(B10,'05_证据映射过程'!$B:$B,0)),"不适用/默认") | F10: =IFERROR(INDEX('06_核验映射过程'!$D:$D,MATCH(B10,'06_核验映射过程'!$B:$B,0)),"默认") | G10: =IFERROR(INDEX('07_权限映射过程'!$D:$D,MATCH(B10,'07_权限映射过程'!$B:$B,0)),"默认") | H10: =IF(D10="","待生成","已生成")
A11: 铝材模块 | B11: 铝材总嵌入排放(kgCO2e/pack) | C11: kgCO2e/pack | D11: =IFERROR(INDEX('10_CBAM中间表'!$D:$D,MATCH(B11,'10_CBAM中间表'!$B:$B,0)),"") | E11: =IFERROR(INDEX('05_证据映射过程'!$E:$E,MATCH(B11,'05_证据映射过程'!$B:$B,0)),"不适用/默认") | F11: =IFERROR(INDEX('06_核验映射过程'!$D:$D,MATCH(B11,'06_核验映射过程'!$B:$B,0)),"默认") | G11: =IFERROR(INDEX('07_权限映射过程'!$D:$D,MATCH(B11,'07_权限映射过程'!$B:$B,0)),"默认") | H11: =IF(D11="","待生成","已生成")
A12: 铝材模块 | B12: 铝材核验状态 | C12: 文本 | D12: =IFERROR(INDEX('10_CBAM中间表'!$D:$D,MATCH(B12,'10_CBAM中间表'!$B:$B,0)),"") | E12: =IFERROR(INDEX('05_证据映射过程'!$E:$E,MATCH(B12,'05_证据映射过程'!$B:$B,0)),"不适用/默认") | F12: =IFERROR(INDEX('06_核验映射过程'!$D:$D,MATCH(B12,'06_核验映射过程'!$B:$B,0)),"默认") | G12: =IFERROR(INDEX('07_权限映射过程'!$D:$D,MATCH(B12,'07_权限映射过程'!$B:$B,0)),"默认") | H12: =IF(D12="","待生成","已生成")
A13: 钢材模块 | B13: 钢材供应商安装点 ID | C13: 文本 | D13: =IFERROR(INDEX('10_CBAM中间表'!$D:$D,MATCH(B13,'10_CBAM中间表'!$B:$B,0)),"") | E13: =IFERROR(INDEX('05_证据映射过程'!$E:$E,MATCH(B13,'05_证据映射过程'!$B:$B,0)),"不适用/默认") | F13: =IFERROR(INDEX('06_核验映射过程'!$D:$D,MATCH(B13,'06_核验映射过程'!$B:$B,0)),"默认") | G13: =IFERROR(INDEX('07_权限映射过程'!$D:$D,MATCH(B13,'07_权限映射过程'!$B:$B,0)),"默认") | H13: =IF(D13="","待生成","已生成")
A14: 钢材模块 | B14: 钢材质量(kg) | C14: kg | D14: =IFERROR(INDEX('10_CBAM中间表'!$D:$D,MATCH(B14,'10_CBAM中间表'!$B:$B,0)),"") | E14: =IFERROR(INDEX('05_证据映射过程'!$E:$E,MATCH(B14,'05_证据映射过程'!$B:$B,0)),"不适用/默认") | F14: =IFERROR(INDEX('06_核验映射过程'!$D:$D,MATCH(B14,'06_核验映射过程'!$B:$B,0)),"默认") | G14: =IFERROR(INDEX('07_权限映射过程'!$D:$D,MATCH(B14,'07_权限映射过程'!$B:$B,0)),"默认") | H14: =IF(D14="","待生成","已生成")
A15: 钢材模块 | B15: 钢材直接排放因子(kgCO2e/kg) | C15: kgCO2e/kg | D15: =IFERROR(INDEX('10_CBAM中间表'!$D:$D,MATCH(B15,'10_CBAM中间表'!$B:$B,0)),"") | E15: =IFERROR(INDEX('05_证据映射过程'!$E:$E,MATCH(B15,'05_证据映射过程'!$B:$B,0)),"不适用/默认") | F15: =IFERROR(INDEX('06_核验映射过程'!$D:$D,MATCH(B15,'06_核验映射过程'!$B:$B,0)),"默认") | G15: =IFERROR(INDEX('07_权限映射过程'!$D:$D,MATCH(B15,'07_权限映射过程'!$B:$B,0)),"默认") | H15: =IF(D15="","待生成","已生成")
... A23: 综合状态 | B23: CBAM 兼容输出结论 | C23: 文本 | D23: =IFERROR(INDEX('10_CBAM中间表'!$D:$D,MATCH(B23,'10_CBAM中间表'!$B:$B,0)),"") | E23: =IFERROR(INDEX('05_证据映射过程'!$E:$E,MATCH(B23,'05_证据映射过程'!$B:$B,0)),"不适用/默认") | F23: =IFERROR(INDEX('06_核验映射过程'!$D:$D,MATCH(B23,'06_核验映射过程'!$B:$B,0)),"默认") | G23: =IFERROR(INDEX('07_权限映射过程'!$D:$D,MATCH(B23,'07_权限映射过程'!$B:$B,0)),"默认") | H23: =IF(D23="","待生成","已生成")

Sheet 04_字段映射过程
A1: 字段映射：从 CATL 输入到 EU / CBAM 输出
A3: 映射层 | B3: 目标字段 | C3: 输入字段代码 | D3: 输入当前值 | E3: 目标制度 | F3: 转换方式 | G3: 转换后结果预览 | H3: 是否关键
A4: 字段映射 | B4: 制造商名称 | C4: manufacturer_name | D4: CATL | E4: EU | F4: 直接映射 | G4: CATL | H4: 是
A5: 字段映射 | B5: 电池型号 | C5: model_code | D5: SXP-CTP-PACK-DEMO-01 | E5: EU+CBAM | F5: 直接映射 | G5: SXP-CTP-PACK-DEMO-01 | H5: 是
A6: 字段映射 | B6: 制造工厂代码 | C6: plant_code | D6: CN-JS-PLANT-DEMO-01 | E6: EU+CBAM | F6: 直接映射 | G6: CN-JS-PLANT-DEMO-01 | H6: 是
A7: 字段映射 | B7: 报告期 | C7: reporting_period | D7: 2025Q4 | E7: EU+CBAM | F7: 公司周期转产品周期 | G7: 2025Q4 | H7: 是
A8: 字段映射 | B8: 声明总碳足迹(kgCO2e/kWh) | C8: pack_capacity_kwh | D8: 72 | E8: EU | F8: 生命周期计算后输出 | G8: 48.971631 | H8: 是
A9: 字段映射 | B9: 原材料阶段(kgCO2e/kWh) | C9: cathode_mass_kg | D9: 140 | E9: EU | F9: 材料质量 x 材料因子 | G9: 44.236111 | H9: 是
A10: 字段映射 | B10: 制造阶段(kgCO2e/kWh) | C10: grid_electricity_kwh | D10: 450 | E10: EU | F10: 能耗 + 工艺排放 + 良率调整 | G10: 4.3605201 | H10: 是
A11: 字段映射 | B11: 再生锂占比 | C11: recycled_lithium_pct | D11: 0.08 | E11: EU | F11: 直接映射 | G11: 0.08 | H11: 是
A12: 字段映射 | B12: 供应链追溯覆盖率 | C12: supplier_traceability_coverage_pct | D12: 0.92 | E12: EU | F12: 直接映射 | G12: 0.92 | H12: 是
A13: 字段映射 | B13: 铝材总嵌入排放(kgCO2e/pack) | C13: aluminium_mass_kg | D13: 80 | E13: CBAM | F13: 铝材质量 x (直接+间接因子) | G13: 1120 | H13: 是
A14: 字段映射 | B14: 钢材总嵌入排放(kgCO2e/pack) | C14: steel_mass_kg | D14: 30 | E14: CBAM | F14: 钢材质量 x (直接+间接因子) | G14: 81 | H14: 是
A15: 字段映射 | B15: 覆盖材料总嵌入排放(kgCO2e/pack) | C15: supplier_pcf_coverage_pct | D15: 0.76 | E15: CBAM | F15: 铝材 + 钢材汇总 | G15: 1201 | H15: 是
A16: 字段映射 | B16: 分层访问矩阵 | C16: access_matrix_status | D16: 齐备 | E16: EU+CBAM | F16: 控制结果可见范围 | G16: 齐备 | H16: 是

Sheet 05_证据映射过程
A1: 证据映射：每个输出字段背后需要什么证据
A3: 目标制度 | B3: 目标字段 | C3: 主要证据 | D3: 触发逻辑 | E3: 证据状态
A4: EU | B4: 制造商名称 | C4: 营业执照 / 年报 | D4: 有主体名称即通过 | E4: 证据齐备
A5: EU | B5: 电池型号 | C5: 型号注册表 / 产品主数据 | D5: 有型号即通过 | E5: 证据齐备
A6: EU | B6: 制造工厂代码 | C6: 工厂注册表 / 生产登记 | D6: 有工厂代码即通过 | E6: 证据齐备
A7: EU | B7: 声明总碳足迹(kgCO2e/kWh) | C7: PCF 研究底稿 / BOM / 能耗 / 运输 / 回收数据 | D7: PCF 底稿齐备且容量>0 | E7: 证据齐备
A8: EU | B8: 再生锂占比 | C8: 质量平衡 / 供应商声明 | D8: 有再生锂输入即通过 | E8: 证据齐备
A9: EU | B9: 尽调政策链接 | C9: 政策文件 / 官网链接 | D9: 有链接即通过 | E9: 证据齐备
A10: EU | B10: 供应链追溯覆盖率 | C10: 追溯台账 / 供应商台账 | D10: 覆盖率>=80% | E10: 证据齐备
A11: EU | B11: 测试报告状态 | C11: 测试报告原件 | D11: 状态=齐备 | E11: 证据齐备
A12: EU | B12: 技术文档状态 | C12: 图纸 / 说明书 / 计算书 | D12: 状态=齐备 | E12: 证据齐备
A13: EU | B13: 护照对象 ID | C13: 结构化数据包 / 接口对象 | D13: 护照数据包=齐备 | E13: 证据齐备
A14: CBAM | B14: 铝材总嵌入排放(kgCO2e/pack) | C14: 铝材安装点数据 / supplier PCF / verifier 报告 | D14: 安装点存在且已核验 | E14: 证据齐备
... A17: CBAM | B17: 供应商 PCF 覆盖率 | C17: supplier PCF 报告 / 声明 | D17: 覆盖率>=70% | E17: 证据齐备

Sheet 06_核验映射过程
A1: 核验映射：谁来确认每一类数据
A3: 目标制度 | B3: 目标字段 | C3: 字段类型 | D3: 核验层级
A4: EU | B4: 制造商名称 | C4: 主体识别 | D4: 内部确认
A5: EU | B5: 电池型号 | C5: 产品主数据 | D5: 内部确认
A6: EU | B6: 制造工厂代码 | C6: 工厂主数据 | D6: 内部确认
A7: EU | B7: 声明总碳足迹(kgCO2e/kWh) | C7: 碳足迹结果 | D7: 第三方/合规核验
A8: EU | B8: 再生锂占比 | C8: 再生材料结果 | D8: 第三方/合规核验
A9: EU | B9: 测试报告状态 | C9: 合规硬材料 | D9: 公告机构/正式合规评估
A10: EU | B10: 技术文档状态 | C10: 合规硬材料 | D10: 公告机构/正式合规评估
A11: CBAM | B11: 铝材总嵌入排放(kgCO2e/pack) | C11: 上游材料排放 | D11: 供应商核验/抽查
A12: CBAM | B12: 钢材总嵌入排放(kgCO2e/pack) | C12: 上游材料排放 | D12: 供应商核验/抽查
A13: CBAM | B13: 覆盖材料总嵌入排放(kgCO2e/pack) | C13: 上游汇总结果 | D13: 供应商核验/抽查

Sheet 07_权限映射过程
A1: 权限映射：谁能看哪些数据
A3: 目标制度 | B3: 目标字段 | C3: 字段类型 | D3: 访问层级
A4: EU | B4: 制造商名称 | C4: 公开识别字段 | D4: 公开
A5: EU | B5: 电池型号 | C5: 产品锚点 | D5: 受限
A6: EU | B6: 制造工厂代码 | C6: 工厂锚点 | D6: 受限
A7: EU | B7: 声明总碳足迹(kgCO2e/kWh) | C7: 公开结果 | D7: 公开
A8: EU | B8: 再生锂占比 | C8: 公开结果 | D8: 公开
A9: EU | B9: 测试报告状态 | C9: 硬材料状态 | D9: 仅公告机构/监管
A10: EU | B10: 技术文档状态 | C10: 硬材料状态 | D10: 仅公告机构/监管
A11: CBAM | B11: 铝材总嵌入排放(kgCO2e/pack) | C11: 上游材料排放 | D11: 受限
A12: CBAM | B12: 钢材总嵌入排放(kgCO2e/pack) | C12: 上游材料排放 | D12: 受限
A13: CBAM | B13: 覆盖材料总嵌入排放(kgCO2e/pack) | C13: 汇总结果 | D13: 受限

Sheet 08_生命周期计算过程
A1: 生命周期碳足迹计算过程（全部自动公式）
A3: 计算模块 | B3: 计算项 | C3: 计算逻辑 | D3: 当前结果预览
A4: 原材料阶段 | B4: 正极材料排放 | C4: 质量 x 排放因子 | D4: 700
A5: 原材料阶段 | B5: 负极材料排放 | C5: 质量 x 排放因子 | D5: 455
A6: 原材料阶段 | B6: 电解液排放 | C6: 质量 x 排放因子 | D6: 280
A7: 原材料阶段 | B7: 隔膜排放 | C7: 质量 x 排放因子 | D7: 54
A8: 原材料阶段 | B8: 铜材排放 | C8: 质量 x 排放因子 | D8: 190
A9: 原材料阶段 | B9: 铝材直接排放 | C9: 质量 x 直接因子 | D9: 720
A10: 原材料阶段 | B10: 铝材间接排放 | C10: 质量 x 间接因子 | D10: 400
A11: 原材料阶段 | B11: 钢材直接排放 | C11: 质量 x 直接因子 | D11: 60
A12: 原材料阶段 | B12: 钢材间接排放 | C12: 质量 x 间接因子 | D12: 21
A13: 原材料阶段 | B13: 塑料件排放 | C13: 质量 x 排放因子 | D13: 75
A14: 原材料阶段 | B14: 其他材料排放 | C14: 质量 x 排放因子 | D14: 230
A15: 原材料阶段 | B15: 原材料阶段合计 | C15: 上述求和 | D15: 3185
... A33: CBAM影子 | B33: 覆盖材料占整包总排放比重 | C33: 覆盖材料总嵌入排放 / 整包总碳足迹 | D33: 0.3406167

Sheet 09_EU中间表
A1: 09_EU中间表
A3: 分组 | B3: 目标字段 | C3: 单位 | D3: 当前结果预览
A4: 基本信息 | B4: 制造商名称 | C4: 文本 | D4: CATL
A5: 基本信息 | B5: 演示产品名称 | C5: 文本 | D5: 神行 PLUS CTP 动力电池包（Demo）
A6: 基本信息 | B6: 电池型号 | C6: 文本 | D6: SXP-CTP-PACK-DEMO-01
A7: 基本信息 | B7: 产品类别 | C7: 文本 | D7: EV battery
A8: 基本信息 | B8: 化学体系 | C8: 文本 | D8: LFP（磷酸铁锂）
A9: 基本信息 | B9: 制造工厂代码 | C9: 文本 | D9: CN-JS-PLANT-DEMO-01
A10: 基本信息 | B10: 制造工厂名称 | C10: 文本 | D10: 江苏时代（Demo）
A11: 基本信息 | B11: 报告期 | C11: 文本 | D11: 2025Q4
A12: 产品参数 | B12: 额定容量(kWh) | C12: kWh | D12: 72
A13: 产品参数 | B13: 标称电压(V) | C13: V | D13: 800
A14: 产品参数 | B14: 循环寿命(cycles) | C14: cycles | D14: 4000
A15: 碳足迹 | B15: 声明总碳足迹(kgCO2e/pack) | C15: kgCO2e/pack | D15: 3525.9574
A16: 碳足迹 | B16: 声明总碳足迹(kgCO2e/kWh) | C16: kgCO2e/kWh | D16: 48.971631
A17: 碳足迹 | B17: 原材料阶段(kgCO2e/kWh) | C17: kgCO2e/kWh | D17: 44.236111
A18: 碳足迹 | B18: 制造阶段(kgCO2e/kWh) | C18: kgCO2e/kWh | D18: 4.3605201
A19: 碳足迹 | B19: 运输阶段(kgCO2e/kWh) | C19: kgCO2e/kWh | D19: 0.58333333
A20: 碳足迹 | B20: 终端回收阶段(kgCO2e/kWh) | C20: kgCO2e/kWh | D20: -0.20833333
A21: 再生材料 | B21: 再生锂占比 | C21: % | D21: 0.08
A22: 再生材料 | B22: 再生钴占比 | C22: % | D22: 0
A23: 再生材料 | B23: 再生镍占比 | C23: % | D23: 0
A24: 再生材料 | B24: 再生铅占比 | C24: % | D24: 0
A25: 尽调与追溯 | B25: 尽调政策链接 | C25: 文本 | D25: https://www.catl.com/
A26: 尽调与追溯 | B26: 关键原材料追溯范围 | C26: 文本 | D26: lithium / graphite / aluminium / copper / steel
A27: 尽调与追溯 | B27: 供应链追溯覆盖率 | C27: % | D27: 0.92
A28: 文件与护照 | B28: 产品碳足迹研究底稿状态 | C28: 文本 | D28: 齐备
A29: 文件与护照 | B29: 测试报告状态 | C29: 文本 | D29: 齐备
A30: 文件与护照 | B30: 技术文档状态 | C30: 文本 | D30: 齐备
A31: 文件与护照 | B31: 护照对象 ID | C31: 文本 | D31: passport-demo-001
A32: 文件与护照 | B32: 个体电池编码前缀 | C32: 文本 | D32: SXP25Q4
A33: 综合状态 | B33: EU 输出完备度 | C33: % | D33: 1
A34: 综合状态 | B34: EU 输出结论 | C34: 文本 | D34: 可直接讲给评委

Sheet 10_CBAM中间表
A1: 10_CBAM中间表
A3: 分组 | B3: 目标字段 | C3: 单位 | D3: 当前结果预览
A4: 基础锚点 | B4: 电池型号 | C4: 文本 | D4: SXP-CTP-PACK-DEMO-01
A5: 基础锚点 | B5: 产品报告期 | C5: 文本 | D5: 2025Q4
A6: 基础锚点 | B6: 上游材料报告期 | C6: 文本 | D6: 2025Q4
A7: 铝材模块 | B7: 铝材供应商安装点 ID | C7: 文本 | D7: AL-SUP-001
A8: 铝材模块 | B8: 铝材质量(kg) | C8: kg | D8: 80
A9: 铝材模块 | B9: 铝材直接排放因子(kgCO2e/kg) | C9: kgCO2e/kg | D9: 9
A10: 铝材模块 | B10: 铝材间接排放因子(kgCO2e/kg) | C10: kgCO2e/kg | D10: 5
A11: 铝材模块 | B11: 铝材总嵌入排放(kgCO2e/pack) | C11: kgCO2e/pack | D11: 1120
A12: 铝材模块 | B12: 铝材核验状态 | C12: 文本 | D12: 已核验
A13: 钢材模块 | B13: 钢材供应商安装点 ID | C13: 文本 | D13: ST-SUP-001
A14: 钢材模块 | B14: 钢材质量(kg) | C14: kg | D14: 30
A15: 钢材模块 | B15: 钢材直接排放因子(kgCO2e/kg) | C15: kgCO2e/kg | D15: 2
A16: 钢材模块 | B16: 钢材间接排放因子(kgCO2e/kg) | C16: kgCO2e/kg | D16: 0.7
A17: 钢材模块 | B17: 钢材总嵌入排放(kgCO2e/pack) | C17: kgCO2e/pack | D17: 81
A18: 钢材模块 | B18: 钢材核验状态 | C18: 文本 | D18: 已核验
A19: 汇总 | B19: 覆盖材料总嵌入排放(kgCO2e/pack) | C19: kgCO2e/pack | D19: 1201
A20: 汇总 | B20: 覆盖材料占整包总排放比重 | C20: % | D20: 0.3406167
A21: 汇总 | B21: 供应商 PCF 覆盖率 | C21: % | D21: 0.76
A22: 综合状态 | B22: CBAM 兼容输出完备度 | C22: % | D22: 1
A23: 综合状态 | B23: CBAM 兼容输出结论 | C23: 文本 | D23: 可作为上游碳数据兼容模块展示
